2024-02-15 19:17:56,812 INFO    StreamThr :382489 [internal.py:wandb_internal():86] W&B internal server running at pid: 382489, started at: 2024-02-15 19:17:56.811800
2024-02-15 19:17:56,813 DEBUG   HandlerThread:382489 [handler.py:handle_request():146] handle_request: status
2024-02-15 19:17:56,821 INFO    WriterThread:382489 [datastore.py:open_for_write():87] open: /home/akshar/Projects/Fraud_Classification/research/wandb/run-20240215_191756-yjlrx8dj/run-yjlrx8dj.wandb
2024-02-15 19:17:56,822 DEBUG   SenderThread:382489 [sender.py:send():382] send: header
2024-02-15 19:17:56,823 DEBUG   SenderThread:382489 [sender.py:send():382] send: run
2024-02-15 19:17:57,496 ERROR   SenderThread:382489 [internal_api.py:execute():373] 403 response executing GraphQL.
2024-02-15 19:17:57,496 ERROR   SenderThread:382489 [internal_api.py:execute():374] {"errors":[{"message":"permission denied","path":["upsertBucket"],"extensions":{"code":"PERMISSION_ERROR"}}],"data":{"upsertBucket":null}}
2024-02-15 19:17:57,497 ERROR   SenderThread:382489 [sender.py:send_run():987] It appears that you do not have permission to access the requested resource. Please reach out to the project owner to grant you access. If you have the correct permissions, verify that there are no issues with your networking setup.(Error 403: Forbidden)
Traceback (most recent call last):
  File "/home/akshar/miniconda3/envs/pytorch/lib/python3.10/site-packages/wandb/sdk/lib/retry.py", line 131, in __call__
    result = self._call_fn(*args, **kwargs)
  File "/home/akshar/miniconda3/envs/pytorch/lib/python3.10/site-packages/wandb/sdk/internal/internal_api.py", line 369, in execute
    return self.client.execute(*args, **kwargs)  # type: ignore
  File "/home/akshar/miniconda3/envs/pytorch/lib/python3.10/site-packages/wandb/vendor/gql-0.2.0/wandb_gql/client.py", line 52, in execute
    result = self._get_result(document, *args, **kwargs)
  File "/home/akshar/miniconda3/envs/pytorch/lib/python3.10/site-packages/wandb/vendor/gql-0.2.0/wandb_gql/client.py", line 60, in _get_result
    return self.transport.execute(document, *args, **kwargs)
  File "/home/akshar/miniconda3/envs/pytorch/lib/python3.10/site-packages/wandb/sdk/lib/gql_request.py", line 59, in execute
    request.raise_for_status()
  File "/home/akshar/miniconda3/envs/pytorch/lib/python3.10/site-packages/requests/models.py", line 1021, in raise_for_status
    raise HTTPError(http_error_msg, response=self)
requests.exceptions.HTTPError: 403 Client Error: Forbidden for url: https://api.wandb.ai/graphql

During handling of the above exception, another exception occurred:

Traceback (most recent call last):
  File "/home/akshar/miniconda3/envs/pytorch/lib/python3.10/site-packages/wandb/sdk/internal/sender.py", line 985, in send_run
    self._init_run(run, config_value_dict)
  File "/home/akshar/miniconda3/envs/pytorch/lib/python3.10/site-packages/wandb/sdk/internal/sender.py", line 1027, in _init_run
    server_run, inserted, server_messages = self._api.upsert_run(
  File "/home/akshar/miniconda3/envs/pytorch/lib/python3.10/site-packages/wandb/apis/normalize.py", line 73, in wrapper
    raise err
  File "/home/akshar/miniconda3/envs/pytorch/lib/python3.10/site-packages/wandb/apis/normalize.py", line 41, in wrapper
    return func(*args, **kwargs)
  File "/home/akshar/miniconda3/envs/pytorch/lib/python3.10/site-packages/wandb/sdk/internal/internal_api.py", line 2216, in upsert_run
    response = self.gql(
  File "/home/akshar/miniconda3/envs/pytorch/lib/python3.10/site-packages/wandb/sdk/internal/internal_api.py", line 341, in gql
    ret = self._retry_gql(
  File "/home/akshar/miniconda3/envs/pytorch/lib/python3.10/site-packages/wandb/sdk/lib/retry.py", line 147, in __call__
    retry_timedelta_triggered = check_retry_fn(e)
  File "/home/akshar/miniconda3/envs/pytorch/lib/python3.10/site-packages/wandb/util.py", line 965, in check_retry_fn
    return fallback_retry_fn(e)
  File "/home/akshar/miniconda3/envs/pytorch/lib/python3.10/site-packages/wandb/util.py", line 907, in no_retry_auth
    raise CommError(
wandb.errors.CommError: It appears that you do not have permission to access the requested resource. Please reach out to the project owner to grant you access. If you have the correct permissions, verify that there are no issues with your networking setup.(Error 403: Forbidden)
2024-02-15 19:18:02,501 DEBUG   HandlerThread:382489 [handler.py:handle_request():146] handle_request: status_report
2024-02-15 19:18:07,502 DEBUG   HandlerThread:382489 [handler.py:handle_request():146] handle_request: status_report
2024-02-15 19:18:12,503 DEBUG   HandlerThread:382489 [handler.py:handle_request():146] handle_request: status_report
2024-02-15 19:18:17,506 DEBUG   HandlerThread:382489 [handler.py:handle_request():146] handle_request: status_report
2024-02-15 19:18:22,508 DEBUG   HandlerThread:382489 [handler.py:handle_request():146] handle_request: status_report
2024-02-15 19:18:27,508 DEBUG   HandlerThread:382489 [handler.py:handle_request():146] handle_request: status_report
2024-02-15 19:18:32,510 DEBUG   HandlerThread:382489 [handler.py:handle_request():146] handle_request: status_report
2024-02-15 19:18:37,510 DEBUG   HandlerThread:382489 [handler.py:handle_request():146] handle_request: status_report
2024-02-15 19:18:42,511 DEBUG   HandlerThread:382489 [handler.py:handle_request():146] handle_request: status_report
2024-02-15 19:18:47,512 DEBUG   HandlerThread:382489 [handler.py:handle_request():146] handle_request: status_report
2024-02-15 19:18:52,513 DEBUG   HandlerThread:382489 [handler.py:handle_request():146] handle_request: status_report
2024-02-15 19:18:57,514 DEBUG   HandlerThread:382489 [handler.py:handle_request():146] handle_request: status_report
2024-02-15 19:19:02,515 DEBUG   HandlerThread:382489 [handler.py:handle_request():146] handle_request: status_report
2024-02-15 19:19:07,516 DEBUG   HandlerThread:382489 [handler.py:handle_request():146] handle_request: status_report
2024-02-15 19:19:12,517 DEBUG   HandlerThread:382489 [handler.py:handle_request():146] handle_request: status_report
2024-02-15 19:19:17,517 DEBUG   HandlerThread:382489 [handler.py:handle_request():146] handle_request: status_report
2024-02-15 19:19:22,518 DEBUG   HandlerThread:382489 [handler.py:handle_request():146] handle_request: status_report
2024-02-15 19:19:27,518 DEBUG   HandlerThread:382489 [handler.py:handle_request():146] handle_request: status_report
2024-02-15 19:19:32,519 DEBUG   HandlerThread:382489 [handler.py:handle_request():146] handle_request: status_report
2024-02-15 19:19:37,519 DEBUG   HandlerThread:382489 [handler.py:handle_request():146] handle_request: status_report
2024-02-15 19:19:42,520 DEBUG   HandlerThread:382489 [handler.py:handle_request():146] handle_request: status_report
2024-02-15 19:19:47,521 DEBUG   HandlerThread:382489 [handler.py:handle_request():146] handle_request: status_report
2024-02-15 19:19:52,522 DEBUG   HandlerThread:382489 [handler.py:handle_request():146] handle_request: status_report
2024-02-15 19:19:57,522 DEBUG   HandlerThread:382489 [handler.py:handle_request():146] handle_request: status_report
2024-02-15 19:20:02,523 DEBUG   HandlerThread:382489 [handler.py:handle_request():146] handle_request: status_report
2024-02-15 19:20:07,524 DEBUG   HandlerThread:382489 [handler.py:handle_request():146] handle_request: status_report
2024-02-15 19:20:12,525 DEBUG   HandlerThread:382489 [handler.py:handle_request():146] handle_request: status_report
2024-02-15 19:20:17,526 DEBUG   HandlerThread:382489 [handler.py:handle_request():146] handle_request: status_report
2024-02-15 19:20:22,526 DEBUG   HandlerThread:382489 [handler.py:handle_request():146] handle_request: status_report
2024-02-15 19:20:27,527 DEBUG   HandlerThread:382489 [handler.py:handle_request():146] handle_request: status_report
2024-02-15 19:20:32,527 DEBUG   HandlerThread:382489 [handler.py:handle_request():146] handle_request: status_report
2024-02-15 19:20:37,528 DEBUG   HandlerThread:382489 [handler.py:handle_request():146] handle_request: status_report
2024-02-15 19:20:42,528 DEBUG   HandlerThread:382489 [handler.py:handle_request():146] handle_request: status_report
2024-02-15 19:20:47,531 DEBUG   HandlerThread:382489 [handler.py:handle_request():146] handle_request: status_report
2024-02-15 19:20:52,531 DEBUG   HandlerThread:382489 [handler.py:handle_request():146] handle_request: status_report
2024-02-15 19:20:57,533 DEBUG   HandlerThread:382489 [handler.py:handle_request():146] handle_request: status_report
2024-02-15 19:21:02,534 DEBUG   HandlerThread:382489 [handler.py:handle_request():146] handle_request: status_report
2024-02-15 19:21:07,535 DEBUG   HandlerThread:382489 [handler.py:handle_request():146] handle_request: status_report
2024-02-15 19:21:12,537 DEBUG   HandlerThread:382489 [handler.py:handle_request():146] handle_request: status_report
2024-02-15 19:21:17,539 DEBUG   HandlerThread:382489 [handler.py:handle_request():146] handle_request: status_report
2024-02-15 19:21:22,540 DEBUG   HandlerThread:382489 [handler.py:handle_request():146] handle_request: status_report
2024-02-15 19:21:27,541 DEBUG   HandlerThread:382489 [handler.py:handle_request():146] handle_request: status_report
2024-02-15 19:21:32,544 DEBUG   HandlerThread:382489 [handler.py:handle_request():146] handle_request: status_report
